<?xml version="1.0" encoding="UTF-8"?>
<!-- Generated by org.testng.reporters.JUnitReportReporter -->
<testsuite hostname="Baburao-PC" name="TestNG.AssertOnGroup" tests="4" failures="1" timestamp="19 Sep 2017 07:26:28 GMT" time="0.032" errors="1">
  <testcase name="test" time="0.016" classname="TestNG.AssertOnGroup">
    <failure type="org.junit.ComparisonFailure" message="expected:&lt;test[]&gt; but was:&lt;test[1]&gt;">
      <![CDATA[org.junit.ComparisonFailure: expected:<test[]> but was:<test[1]>
	at org.junit.Assert.assertEquals(Assert.java:115)
	at org.junit.Assert.assertEquals(Assert.java:144)
	at TestNG.AssertOnGroup.test(AssertOnGroup.java:17)
	at sun.reflect.NativeMethodAccessorImpl.invoke0(Native Method)
	at sun.reflect.NativeMethodAccessorImpl.invoke(NativeMethodAccessorImpl.java:62)
	at sun.reflect.DelegatingMethodAccessorImpl.invoke(DelegatingMethodAccessorImpl.java:43)
	at java.lang.reflect.Method.invoke(Method.java:498)
	at org.testng.internal.MethodInvocationHelper.invokeMethod(MethodInvocationHelper.java:85)
	at org.testng.internal.Invoker.invokeMethod(Invoker.java:639)
	at org.testng.internal.Invoker.invokeTestMethod(Invoker.java:816)
	at org.testng.internal.Invoker.invokeTestMethods(Invoker.java:1124)
	at org.testng.internal.TestMethodWorker.invokeTestMethods(TestMethodWorker.java:125)
	at org.testng.internal.TestMethodWorker.run(TestMethodWorker.java:108)
	at org.testng.TestRunner.privateRun(TestRunner.java:774)
	at org.testng.TestRunner.run(TestRunner.java:624)
	at org.testng.SuiteRunner.runTest(SuiteRunner.java:359)
	at org.testng.SuiteRunner.access$000(SuiteRunner.java:39)
	at org.testng.SuiteRunner$SuiteWorker.run(SuiteRunner.java:393)
	at org.testng.internal.thread.ThreadUtil$2.call(ThreadUtil.java:64)
	at java.util.concurrent.FutureTask.run(FutureTask.java:266)
	at java.util.concurrent.ThreadPoolExecutor.runWorker(ThreadPoolExecutor.java:1149)
	at java.util.concurrent.ThreadPoolExecutor$Worker.run(ThreadPoolExecutor.java:624)
	at java.lang.Thread.run(Thread.java:748)
]]>
    </failure>
  </testcase> <!-- test -->
  <testcase name="test1" time="0.016" classname="TestNG.AssertOnGroup"/>
  <testcase name="test4" time="0.000" classname="TestNG.AssertOnGroup"/>
  <testcase name="test2" time="0.000" classname="TestNG.AssertOnGroup">
    <error type="java.lang.Throwable" message="Method AssertOnGroup.test2()[pri:0, instance:TestNG.AssertOnGroup@675d3402] depends on not successfully finished methods in group &quot;james&quot;">
      <![CDATA[java.lang.Throwable: Method AssertOnGroup.test2()[pri:0, instance:TestNG.AssertOnGroup@675d3402] depends on not successfully finished methods in group "james"
	at org.testng.internal.Invoker.invokeTestMethods(Invoker.java:1033)
	at org.testng.internal.TestMethodWorker.invokeTestMethods(TestMethodWorker.java:125)
	at org.testng.internal.TestMethodWorker.run(TestMethodWorker.java:108)
	at org.testng.TestRunner.privateRun(TestRunner.java:774)
	at org.testng.TestRunner.run(TestRunner.java:624)
	at org.testng.SuiteRunner.runTest(SuiteRunner.java:359)
	at org.testng.SuiteRunner.access$000(SuiteRunner.java:39)
	at org.testng.SuiteRunner$SuiteWorker.run(SuiteRunner.java:393)
	at org.testng.internal.thread.ThreadUtil$2.call(ThreadUtil.java:64)
	at java.util.concurrent.FutureTask.run(FutureTask.java:266)
	at java.util.concurrent.ThreadPoolExecutor.runWorker(ThreadPoolExecutor.java:1149)
	at java.util.concurrent.ThreadPoolExecutor$Worker.run(ThreadPoolExecutor.java:624)
	at java.lang.Thread.run(Thread.java:748)
]]>
    </error>
  </testcase> <!-- test2 -->
</testsuite> <!-- TestNG.AssertOnGroup -->
